Workbook

Sheet Read Me
A1: CITI PRODUCT MANAGEMENT LEAD ANALYST — ADVANCED EXPENSE MANAGEMENT & PRODUCT-MIX WORKBOOK
B3: Built for the Product Management Lead Analyst role: expense management, acquisition targets, revenue performance, and product-mix decisions.
B4: Every category, ratio, and benchmark below is sourced from named 2025/2026 industry research (see Assumptions tab) — replace blue cells with your desk's actual figures.
B6: PURPOSE
B7: This role is judged on 'expense management goals' and 'product financial performance' in the same breath as market share and client positioning. This workbook gives you one steerable model that turns those two mandates into a single view: for each product in the mix, what does it cost to acquire and run, and how much value does it actually contribute after every real cost is loaded in.
B11: WORKBOOK STRUCTURE
B12: 2. Assumptions | C12: Scenario selector (Base/Upside/Downside) plus every macro, CAC, and cost-ratio driver, each with its named source (Fintel Connect/Forbes, First Page Sage, McKinsey, Gartner, Federal Reserve Bank of St. Louis, Glassdoor/PayScale).
B13: 3. Product Mix | C13: Unit economics for four representative Citi-style product lines (Credit Cards, Retail Banking, Small Business Banking, Wealth & Affluent Banking): revenue, CAC, headcount, contribution margin, LTV:CAC, and CAC-payback, each flagged red/amber/green against target.
B14: 4. Expense Detail & Budget Control | C14: Company-wide expense by category with quarterly phasing, actuals entry, variance, and RAG status — a real budget-control cockpit for the 'expense management goals' responsibility.
B15: 5. 5-Yr Projection | C15: Five-year forward view by product and in total: compounding revenue growth, operating-leverage-adjusted expense ratios, contribution margin, and NPV of the margin stream at your WACC.
B16: 6. Sensitivity & Scenarios | C16: Side-by-side Base/Upside/Downside Year-5 outcomes, plus single-variable sensitivity of margin and LTV:CAC to CAC, marketing spend, and growth-rate shocks — a ready-made 'what if' for a budget review.
B17: 7. Dashboard | C17: One-page stakeholder view: KPI cards, expense-mix pie, contribution-margin-by-product bar, 5-year revenue/expense trend, and LTV:CAC-by-product chart.
B19: HOW TO STEER THIS MODEL
B20: - | C20: Set the Active Planning Scenario dropdown on Assumptions (cell C5) to Base Case, Upside, or Downside — this re-drives growth, marketing, technology, compliance, and overhead assumptions through Product Mix and the 5-Yr Projection instantly.
B21: - | C21: Edit any BLUE cell — product revenue, CAC, headcount, or cost-ratio assumptions — and every downstream calculation, KPI, and chart recalculates.
B22: - | C22: Enter quarterly actuals on Expense Detail as each quarter closes; variance and RAG status update live to flag categories running over budget.
B23: - | C23: Use Sensitivity & Scenarios to pressure-test a decision before it goes into a business review, e.g. 'what happens to contribution margin if Small Business Banking CAC rises 20%?'
B25: COLOR CODING LEGEND
B26: Blue text | C26: Hardcoded input — change this for your own planning scenario.
B27: Black text | C27: Formula or calculation — derived automatically; do not overwrite.
B28: Green text | C28: Link pulling a value from another worksheet within this workbook.
B29: Red RAG flag | C29: A ratio outside its healthy benchmark range (e.g., LTV:CAC below target, budget variance over threshold).
B31: REALISTIC OUTPUTS THIS WORKBOOK IS DESIGNED TO PRODUCE
B32: - | C32: A defensible, per-product contribution-margin ranking, directly supporting the role's 'product financial performance and expense management goals' responsibility.
B33: - | C33: An early-warning system on unit economics: any product whose LTV:CAC falls below 4.0x or whose CAC-payback exceeds 18 months is automatically flagged — feeding straight into pricing, targeting, and channel-mix decisions referenced in the job description.
B34: - | C34: A quarterly budget-control cockpit with RAG-flagged variance, so overspend is caught within the quarter rather than at year-end.
B35: - | C35: A 5-year, NPV-based view of which products compound value fastest — useful directly for the 'strategic product roadmap' and 'acquisition targets' conversations with product managers and marketing partners.
B36: - | C36: A stress-tested view of the mix under Upside/Downside scenarios, so risk can be 'appropriately assessed' — as the role requires — before committing budget.

Sheet Assumptions
A1: ASSUMPTIONS — MASTER CONTROL PANEL
B3: Change the Active Planning Scenario or any blue input; every other sheet recalculates from here.
B5: Active Planning Scenario: | C5: Base Case | E5: Drives revenue growth and cost-ratio assumptions used in Product Mix and 5-Yr Projection.
B7: 1. MACRO & SCENARIO GROWTH ASSUMPTIONS
B8: Driver | C8: Base Case | D8: Upside | E8: Downside | F8: Unit | G8: Source / Rationale
B9: Revenue Growth Rate (YoY) | C9: 0.07 | D9: 0.11 | E9: 0.02 | F9: % | G9: Illustrative planning range — replace with your desk's FY plan / board-approved growth target.
B10: Brand & Retention Marketing (% of Revenue) | C10: 0.035 | D10: 0.03 | E10: 0.045 | F10: % | G10: Financial-services marketing budgets run ~5-10% of revenue, averaging 7.5% in 2023 (Gartner CMO Spend Survey; WebFX 2026 Financial Services Marketing Benchmark). This line excludes CAC-driven acquisition spend, modeled separately per product below.
B11: Technology / IT Spend (% of Revenue) | C11: 0.08 | D11: 0.07 | E11: 0.095 | F11: % | G11: Banking/financial-services technology spend runs 6-12% of revenue with an ~8% median (McKinsey Oct-2024; AlixPartners 2025; SouthState Correspondent Division, median 8.1% in 2023).
B12: Compliance & Risk Spend (% of Revenue) | C12: 0.045 | D12: 0.04 | E12: 0.055 | F12: % | G12: Compliance costs run 2.9-8.7% of non-interest expense (Federal Reserve Bank of St. Louis, 2016 study of bank compliance costs); firm-wide direct+indirect cost can reach ~19% of revenue at the high end (Model Office / Fidelity Adviser Solutions). Modeled here as a moderate product-level allocation.
B13: Corporate Overhead Allocation (% of Revenue) | C13: 0.06 | D13: 0.055 | E13: 0.07 | F13: % | G13: Shared-services / occupancy / central-function allocation — align to your entity's cost-allocation policy.
B14: Headcount Cost Inflation (YoY) | C14: 0.055 | D14: 0.045 | E14: 0.035 | F14: % | G14: Blended annual compensation inflation assumption for BFSI product, engineering and analyst talent.
B15: Annual Opex-Ratio Efficiency Improvement | C15: 0.01 | D15: 0.02 | E15: -0.01 | F15: % | G15: Operating-leverage assumption: expense-to-revenue ratio improves (Upside) or deteriorates (Downside) this many points per year in the 5-Yr Projection.
B17: 2. UNIT ECONOMICS & WORKFORCE ASSUMPTIONS
B18: Driver | C18: Value | F18: Unit | G18: Source / Rationale
B19: Average Fully-Loaded Cost per FTE ($/yr) | C19: 165000 | F19: $ | G19: Blended cost across Product Lead Analyst / Product Manager / Analyst roles: Financial Services Senior Product Manager median total pay $190,403 (Glassdoor 2026); Product Manager, Banking average $103,524 (PayScale 2025). Loaded ~15-20% for benefits/overhead onto a blended base.
B20: Base Fiscal Year (Year 0) | C20: 2026 | F20: FY | G20: Current/base year; the 5-Yr Projection models FY+1 through FY+5 from here.
B21: LTV:CAC Target Ratio | C21: 4 | F21: x | G21: 4:1 is a widely cited healthy-economics benchmark for acquisition-funded growth.
B22: CAC Payback Period Target | C22: 18 | F22: months | G22: Target period to recover fully-loaded CAC from the variable contribution a new customer generates.
B23: Average Customer Tenure (default, if not overridden per product) | C23: 6 | F23: years | G23: Used to derive simplified customer lifetime value (LTV) where a product-specific tenure is not entered.
B24: WACC / Discount Rate | C24: 0.1 | F24: % | G24: Used to NPV the 5-year contribution-margin stream; align to your treasury's hurdle rate.
B25: Effective Tax Rate | C25: 0.25 | F25: % | G25: Applied for an indicative after-tax profitability view.
B26: Planning Horizon | C26: 5 | F26: years | G26: Number of forecast years modeled in the 5-Yr Projection sheet.
B28: 3. BENCHMARK CUSTOMER ACQUISITION COST (CAC) BY BANK PRODUCT TYPE — REFERENCE (DRIVES PRODUCT MIX INPUTS)
B29: Bank / Product Type | C29: Benchmark CAC ($) | G29: Source
B30: Credit Card Provider | C30: $167 | G30: First Page Sage, 'Average CAC in Banking' (data gathered June 2018-Nov 2024) — average across credit-card-provider issuers.
B31: Retail Banking — Consumer | C31: $561 | G31: First Page Sage — average CAC for consumer-facing retail banks.
B32: Small Business Banking | C32: $607 | G32: First Page Sage — average CAC for small-business banking customers.
B33: Wealth / Affluent (UHNW-oriented) Banking | C33: $855 | G33: First Page Sage — average CAC for ultra-high-net-worth (UHNW) banking customers.
B34: Middle Market / Commercial | C34: $1,120 | G34: First Page Sage — average CAC for middle-market commercial banking customers, for reference.
B35: Online / Digital-First Bank | C35: $290 | G35: First Page Sage — average CAC for digital-only bank models, for reference.
B37: 4. SELECTED SCENARIO VALUES (AUTO-DRIVEN BY THE DROPDOWN ABOVE — USED BY OTHER SHEETS)
B38: Driver | C38: Selected Value | F38: Unit | G38: Formula Logic
B39: Revenue Growth Rate (YoY) | C39: =INDEX(C9:E9,MATCH($C$5,$C$8:$E$8,0)) -> 0.07 | F39: % | G39: Auto-selects Base/Upside/Downside column above based on scenario dropdown (C5)
B40: Brand & Retention Marketing (% of Revenue) | C40: =INDEX(C10:E10,MATCH($C$5,$C$8:$E$8,0)) -> 0.035 | F40: % | G40: Auto-selects Base/Upside/Downside column above based on scenario dropdown (C5)
B41: Technology / IT Spend (% of Revenue) | C41: =INDEX(C11:E11,MATCH($C$5,$C$8:$E$8,0)) -> 0.08 | F41: % | G41: Auto-selects Base/Upside/Downside column above based on scenario dropdown (C5)
B42: Compliance & Risk Spend (% of Revenue) | C42: =INDEX(C12:E12,MATCH($C$5,$C$8:$E$8,0)) -> 0.045 | F42: % | G42: Auto-selects Base/Upside/Downside column above based on scenario dropdown (C5)
B43: Corporate Overhead Allocation (% of Revenue) | C43: =INDEX(C13:E13,MATCH($C$5,$C$8:$E$8,0)) -> 0.06 | F43: % | G43: Auto-selects Base/Upside/Downside column above based on scenario dropdown (C5)
B44: Headcount Cost Inflation (YoY) | C44: =INDEX(C14:E14,MATCH($C$5,$C$8:$E$8,0)) -> 0.055 | F44: % | G44: Auto-selects Base/Upside/Downside column above based on scenario dropdown (C5)
B45: Annual Opex-Ratio Efficiency Improvement | C45: =INDEX(C15:E15,MATCH($C$5,$C$8:$E$8,0)) -> 0.01 | F45: % | G45: Auto-selects Base/Upside/Downside column above based on scenario dropdown (C5)

Sheet Product Mix
A1: PRODUCT MIX — UNIT ECONOMICS & CONTRIBUTION MARGIN BY PRODUCT
B3: CAC inputs are pre-populated from the First Page Sage banking-CAC benchmarks on the Assumptions tab. All other BLUE cells are illustrative — replace with your desk's actual product P&L, customer, and headcount data.
B6: Metric | C6: Credit Cards | D6: Retail Banking (Deposits & Digital) | E6: Small Business Banking | F6: Wealth & Affluent Banking | G6: TOTAL / BLENDED
B7: CURRENT-STATE INPUTS
B8: Current Annual Product Revenue ($mm) | C8: 480 | D8: 340 | E8: 210 | F8: 165 | G8: =SUM(C8:F8) -> 1195
B9: Current Active Customers (000s) | C9: 1150 | D9: 2600 | E9: 78 | F9: 45 | G9: =SUM(C9:F9) -> 3873
B10: Customer Acquisition Cost — CAC ($) | C10: 167 | D10: 561 | E10: 607 | F10: 855 | G10: =SUM(C10:F10) -> 2190
B11: New Customer Acquisition Target — Year 1 (000s) | C11: 180 | D11: 55 | E11: 9 | F11: 5 | G11: =SUM(C11:F11) -> 249
B12: Dedicated FTE Headcount | C12: 42 | D12: 58 | E12: 30 | F12: 22 | G12: =SUM(C12:F12) -> 152
B13: Technology Intensity Weight (1.0 = average) | C13: 1.3 | D13: 1.5 | E13: 0.8 | F13: 0.9
B14: Compliance/Risk Intensity Weight (1.0 = average) | C14: 1.4 | D14: 1 | E14: 1.5 | F14: 1.2
B15: Gross Revenue Yield / Margin (% of revenue, pre-opex) | C15: 0.55 | D15: 0.36 | E15: 0.46 | F15: 0.4
B16: Revenue Growth Override (blank = use scenario default)
B17: Customer Tenure Override, years (blank = use global default) | C17: 4 | D17: 8 | E17: 6 | F17: 9
B19: CALCULATED UNIT ECONOMICS & EXPENSE ALLOCATION
B20: Applied Revenue Growth Rate (%) | C20: =IF(C16="",Sel_GrowthRate,C16) -> 0.07 | D20: =IF(D16="",Sel_GrowthRate,D16) -> 0.07 | E20: =IF(E16="",Sel_GrowthRate,E16) -> 0.07 | F20: =IF(F16="",Sel_GrowthRate,F16) -> 0.07
B21: Customer Acquisition Marketing Spend ($mm) | C21: =C10*C11/1000 -> 30.06 | D21: =D10*D11/1000 -> 30.855 | E21: =E10*E11/1000 -> 5.463 | F21: =F10*F11/1000 -> 4.275 | G21: =SUM(C21:F21) -> 70.653
B22: Brand & Retention Marketing Spend ($mm) | C22: =C8*Sel_MktgPct -> 16.8 | D22: =D8*Sel_MktgPct -> 11.9 | E22: =E8*Sel_MktgPct -> 7.35 | F22: =F8*Sel_MktgPct -> 5.775 | G22: =SUM(C22:F22) -> 41.825
B23: Total Marketing Spend ($mm) | C23: =C21+C22 -> 46.86 | D23: =D21+D22 -> 42.755 | E23: =E21+E22 -> 12.813 | F23: =F21+F22 -> 10.05 | G23: =SUM(C23:F23) -> 112.478
B24: Technology Cost ($mm) | C24: =C8*Sel_ITPct*C13 -> 49.92 | D24: =D8*Sel_ITPct*D13 -> 40.8 | E24: =E8*Sel_ITPct*E13 -> 13.44 | F24: =F8*Sel_ITPct*F13 -> 11.88 | G24: =SUM(C24:F24) -> 116.04
B25: Compliance & Risk Cost ($mm) | C25: =C8*Sel_CompliancePct*C14 -> 30.24 | D25: =D8*Sel_CompliancePct*D14 -> 15.3 | E25: =E8*Sel_CompliancePct*E14 -> 14.175 | F25: =F8*Sel_CompliancePct*F14 -> 8.91 | G25: =SUM(C25:F25) -> 68.625
B26: Headcount Cost ($mm) | C26: =C12*CostPerFTE/1000000 -> 6.93 | D26: =D12*CostPerFTE/1000000 -> 9.57 | E26: =E12*CostPerFTE/1000000 -> 4.95 | F26: =F12*CostPerFTE/1000000 -> 3.63 | G26: =SUM(C26:F26) -> 25.08
B27: Corporate Overhead Allocation ($mm) | C27: =C8*Sel_OverheadPct -> 28.8 | D27: =D8*Sel_OverheadPct -> 20.4 | E27: =E8*Sel_OverheadPct -> 12.6 | F27: =F8*Sel_OverheadPct -> 9.9 | G27: =SUM(C27:F27) -> 71.7
B28: Total Operating Expense ($mm) | C28: =C23+C24+C25+C26+C27 -> 162.75 | D28: =D23+D24+D25+D26+D27 -> 128.825 | E28: =E23+E24+E25+E26+E27 -> 57.978 | F28: =F23+F24+F25+F26+F27 -> 44.37 | G28: =SUM(C28:F28) -> 393.923
B29: Gross Profit — Revenue x Yield ($mm) | C29: =C8*C15 -> 264 | D29: =D8*D15 -> 122.4 | E29: =E8*E15 -> 96.6 | F29: =F8*F15 -> 66 | G29: =SUM(C29:F29) -> 549
B30: Contribution Margin ($mm) | C30: =C29-C28 -> 101.25 | D30: =D29-D28 -> -6.425 | E30: =E29-E28 -> 38.622 | F30: =F29-F28 -> 21.63 | G30: =SUM(C30:F30) -> 155.077
B31: Contribution Margin (% of Revenue) | C31: =C30/C8 -> 0.2109375 | D31: =D30/D8 -> -0.018897059 | E31: =E30/E8 -> 0.18391429 | F31: =F30/F8 -> 0.13109091 | G31: =G30/G8 -> 0.12977155
B32: Expense-to-Revenue Ratio (%) | C32: =C28/C8 -> 0.3390625 | D32: =D28/D8 -> 0.37889706 | E32: =E28/E8 -> 0.27608571 | F32: =F28/F8 -> 0.26890909 | G32: =G28/G8 -> 0.32964268
B33: Applied Customer Tenure (years) | C33: =IF(C17="",AvgTenure,C17) -> 4 | D33: =IF(D17="",AvgTenure,D17) -> 8 | E33: =IF(E17="",AvgTenure,E17) -> 6 | F33: =IF(F17="",AvgTenure,F17) -> 9
B34: Average Revenue Per Customer — ARPU ($) | C34: =C8*1000000/(C9*1000) -> 417.3913 | D34: =D8*1000000/(D9*1000) -> 130.76923 | E34: =E8*1000000/(E9*1000) -> 2692.3077 | F34: =F8*1000000/(F9*1000) -> 3666.6667 | G34: =G8*1000000/(G9*1000) -> 308.54635
B35: Customer Lifetime Value — LTV ($) | C35: =C34*C15*C33 -> 918.26087 | D35: =D34*D15*D33 -> 376.61538 | E35: =E34*E15*E33 -> 7430.7692 | F35: =F34*F15*F33 -> 13200 | G35: =SUMPRODUCT(C35:F35,C9:F9)/G9 -> 828.50503
B36: LTV : CAC Ratio (x) | C36: =C35/C10 -> 5.4985681 | D36: =D35/D10 -> 0.67132867 | E36: =E35/E10 -> 12.241794 | F36: =F35/F10 -> 15.438596 | G36: =G35/(SUM(C21:F21)*1000000/SUM(C11:F11)/1000) -> 2.9198725
B37: CAC Payback Period (months) | C37: =C10/((C34*C15)/12) -> 8.7295455 | D37: =D10/((D34*D15)/12) -> 143 | E37: =E10/((E34*E15)/12) -> 5.8814907 | F37: =F10/((F34*F15)/12) -> 6.9954545 | G37: =(SUM(C21:F21)*1000000/SUM(C11:F11)/1000)/((G34*(G29/G8))/12) -> 24.020811
B39: Analyst note: Retail Banking's CAC/ARPU ratio only clears target when read as a relationship-acquisition cost (recouped via cross-sell of Credit Cards, lending, and Wealth products), not as a stand-alone deposit-product return — a common, real pattern in retail banking economics.

Sheet Expense Detail & Budget Control
A1: EXPENSE DETAIL & QUARTERLY BUDGET CONTROL
B3: Annual budget pulls live from Product Mix totals. Enter quarterly actuals (blue) as they close; variance and RAG status update automatically.
B5: Expense Category | C5: Annual Budget ($mm) | D5: Q1 Budget | E5: Q2 Budget | F5: Q3 Budget | G5: Q4 Budget | H5: Q1 Actual | I5: Q2 Actual | J5: Q3 Actual | K5: Q4 Actual | L5: FY Variance ($mm) | M5: Status
B6: QUARTERLY PHASING ASSUMPTION (% OF ANNUAL BUDGET PER QUARTER — EDIT IF SEASONALITY DIFFERS)
B7: Default phasing (equal, editable) | D7: 0.25 | E7: 0.25 | F7: 0.25 | G7: 0.25 | H7: Total must equal 100% — adjust for seasonal spend patterns (e.g., higher Q4 marketing during holiday acquisition campaigns).
B9: EXPENSE CATEGORIES (BUDGET LINKED TO PRODUCT MIX TOTALS)
B10: Total Marketing Spend (Acquisition + Brand/Retention) | C10: ='Product Mix'!$G$23 -> 112.478 | D10: =$C10*D$7 -> 28.1195 | E10: =$C10*E$7 -> 28.1195 | F10: =$C10*F$7 -> 28.1195 | G10: =$C10*G$7 -> 28.1195 | H10: 0 | I10: 0 | J10: 0 | K10: 0 | L10: =(H10+I10+J10+K10)-C10 -> -112.478 | M10: =IF(SUM(H10:K10)=0,"No actuals yet",IF(L10/C10>0.1,"Over Budget",IF(L10/C10<-0.1,"Under-spend",IF(ABS(L10/C10)<=0.05,"On Track","Watch")))) -> No actuals yet
B11: Technology & Infrastructure | C11: ='Product Mix'!$G$24 -> 116.04 | D11: =$C11*D$7 -> 29.01 | E11: =$C11*E$7 -> 29.01 | F11: =$C11*F$7 -> 29.01 | G11: =$C11*G$7 -> 29.01 | H11: 0 | I11: 0 | J11: 0 | K11: 0 | L11: =(H11+I11+J11+K11)-C11 -> -116.04 | M11: =IF(SUM(H11:K11)=0,"No actuals yet",IF(L11/C11>0.1,"Over Budget",IF(L11/C11<-0.1,"Under-spend",IF(ABS(L11/C11)<=0.05,"On Track","Watch")))) -> No actuals yet
B12: Compliance & Risk | C12: ='Product Mix'!$G$25 -> 68.625 | D12: =$C12*D$7 -> 17.15625 | E12: =$C12*E$7 -> 17.15625 | F12: =$C12*F$7 -> 17.15625 | G12: =$C12*G$7 -> 17.15625 | H12: 0 | I12: 0 | J12: 0 | K12: 0 | L12: =(H12+I12+J12+K12)-C12 -> -68.625 | M12: =IF(SUM(H12:K12)=0,"No actuals yet",IF(L12/C12>0.1,"Over Budget",IF(L12/C12<-0.1,"Under-spend",IF(ABS(L12/C12)<=0.05,"On Track","Watch")))) -> No actuals yet
B13: People / Headcount Cost | C13: ='Product Mix'!$G$26 -> 25.08 | D13: =$C13*D$7 -> 6.27 | E13: =$C13*E$7 -> 6.27 | F13: =$C13*F$7 -> 6.27 | G13: =$C13*G$7 -> 6.27 | H13: 0 | I13: 0 | J13: 0 | K13: 0 | L13: =(H13+I13+J13+K13)-C13 -> -25.08 | M13: =IF(SUM(H13:K13)=0,"No actuals yet",IF(L13/C13>0.1,"Over Budget",IF(L13/C13<-0.1,"Under-spend",IF(ABS(L13/C13)<=0.05,"On Track","Watch")))) -> No actuals yet
B14: Corporate Overhead Allocation | C14: ='Product Mix'!$G$27 -> 71.7 | D14: =$C14*D$7 -> 17.925 | E14: =$C14*E$7 -> 17.925 | F14: =$C14*F$7 -> 17.925 | G14: =$C14*G$7 -> 17.925 | H14: 0 | I14: 0 | J14: 0 | K14: 0 | L14: =(H14+I14+J14+K14)-C14 -> -71.7 | M14: =IF(SUM(H14:K14)=0,"No actuals yet",IF(L14/C14>0.1,"Over Budget",IF(L14/C14<-0.1,"Under-spend",IF(ABS(L14/C14)<=0.05,"On Track","Watch")))) -> No actuals yet
B15: Contingency / Unallocated Reserve (3% of subtotal) | C15: =SUM(C10:C14)*0.03 -> 11.81769
B16: TOTAL EXPENSE BUDGET | C16: =SUM(C10:C15) -> 405.74069 | D16: =SUM(D10:D15) -> 98.48075 | E16: =SUM(E10:E15) -> 98.48075 | F16: =SUM(F10:F15) -> 98.48075 | G16: =SUM(G10:G15) -> 98.48075 | H16: =SUM(H10:H15) -> 0 | I16: =SUM(I10:I15) -> 0 | J16: =SUM(J10:J15) -> 0 | ... L16: =SUM(L10:L15) -> -393.923
B18: STATUS LEGEND
B19: On Track | C19: Within +/-5% of phased budget
B20: Watch | C20: 5-10% variance — monitor
B21: Over Budget | C21: >10% over phased budget — action required
B22: Under-spend | C22: >10% under phased budget — check for delayed execution

Sheet 5-Yr Projection
A1: 5-YEAR PROJECTION — REVENUE, EXPENSE & CONTRIBUTION MARGIN BY PRODUCT
B3: Driven by the Active Planning Scenario on Assumptions. Revenue compounds at the applied growth rate; the expense ratio improves/deteriorates each year per the Opex-Ratio Efficiency assumption.
B6: Fiscal Year Label -> | C6: ="FY"&(BaseFY+1) -> FY2027 | D6: ="FY"&(BaseFY+2) -> FY2028 | E6: ="FY"&(BaseFY+3) -> FY2029 | F6: ="FY"&(BaseFY+4) -> FY2030 | G6: ="FY"&(BaseFY+5) -> FY2031
B7: Metric | C7: Year 1 | D7: Year 2 | E7: Year 3 | F7: Year 4 | G7: Year 5
B9: CREDIT CARDS
B10: Revenue ($mm) | C10: ='Product Mix'!C$8*(1+'Product Mix'!C$19) -> 480 | D10: =C10*(1+'Product Mix'!C$19) -> 480 | E10: =D10*(1+'Product Mix'!C$19) -> 480 | F10: =E10*(1+'Product Mix'!C$19) -> 480 | G10: =F10*(1+'Product Mix'!C$19) -> 480
B11: Expense-to-Revenue Ratio (%) | C11: ='Product Mix'!C$32*(1-Sel_OpexEfficiency) -> 0.33567188 | D11: =C11*(1-Sel_OpexEfficiency) -> 0.33231516 | E11: =D11*(1-Sel_OpexEfficiency) -> 0.328992 | F11: =E11*(1-Sel_OpexEfficiency) -> 0.32570208 | G11: =F11*(1-Sel_OpexEfficiency) -> 0.32244506
B12: Total Operating Expense ($mm) | C12: =C10*C11 -> 161.1225 | D12: =D10*D11 -> 159.51128 | E12: =E10*E11 -> 157.91616 | F12: =F10*F11 -> 156.337 | G12: =G10*G11 -> 154.77363
B13: Gross Profit ($mm) | C13: =C10*'Product Mix'!C$15 -> 264 | D13: =D10*'Product Mix'!C$15 -> 264 | E13: =E10*'Product Mix'!C$15 -> 264 | F13: =F10*'Product Mix'!C$15 -> 264 | G13: =G10*'Product Mix'!C$15 -> 264
B14: Contribution Margin ($mm) | C14: =C13-C12 -> 102.8775 | D14: =D13-D12 -> 104.48873 | E14: =E13-E12 -> 106.08384 | F14: =F13-F12 -> 107.663 | G14: =G13-G12 -> 109.22637
B15: Contribution Margin (% of Revenue) | C15: =C14/C10 -> 0.21432813 | D15: =D14/D10 -> 0.21768484 | E15: =E14/E10 -> 0.221008 | F15: =F14/F10 -> 0.22429792 | G15: =G14/G10 -> 0.22755494
B16: NPV of 5-Year Contribution Margin ($mm) | C16: =NPV(WACC,C14:G14) -> 400.93793
B18: RETAIL BANKING (DEPOSITS & DIGITAL)
B19: Revenue ($mm) | C19: ='Product Mix'!D$8*(1+'Product Mix'!D$19) -> 340 | D19: =C19*(1+'Product Mix'!D$19) -> 340 | E19: =D19*(1+'Product Mix'!D$19) -> 340 | F19: =E19*(1+'Product Mix'!D$19) -> 340 | G19: =F19*(1+'Product Mix'!D$19) -> 340
B20: Expense-to-Revenue Ratio (%) | C20: ='Product Mix'!D$32*(1-Sel_OpexEfficiency) -> 0.37510809 | D20: =C20*(1-Sel_OpexEfficiency) -> 0.37135701 | E20: =D20*(1-Sel_OpexEfficiency) -> 0.36764344 | F20: =E20*(1-Sel_OpexEfficiency) -> 0.363967 | G20: =F20*(1-Sel_OpexEfficiency) -> 0.36032733
B21: Total Operating Expense ($mm) | C21: =C19*C20 -> 127.53675 | D21: =D19*D20 -> 126.26138 | E21: =E19*E20 -> 124.99877 | F21: =F19*F20 -> 123.74878 | G21: =G19*G20 -> 122.51129
B22: Gross Profit ($mm) | C22: =C19*'Product Mix'!D$15 -> 122.4 | D22: =D19*'Product Mix'!D$15 -> 122.4 | E22: =E19*'Product Mix'!D$15 -> 122.4 | F22: =F19*'Product Mix'!D$15 -> 122.4 | G22: =G19*'Product Mix'!D$15 -> 122.4
B23: Contribution Margin ($mm) | C23: =C22-C21 -> -5.13675 | D23: =D22-D21 -> -3.8613825 | E23: =E22-E21 -> -2.5987687 | F23: =F22-F21 -> -1.348781 | G23: =G22-G21 -> -0.11129318
B24: Contribution Margin (% of Revenue) | C24: =C23/C19 -> -0.015108088 | D24: =D23/D19 -> -0.011357007 | E24: =E23/E19 -> -0.0076434373 | F24: =F23/F19 -> -0.0039670029 | G24: =G23/G19 -> -0.00032733288
B25: NPV of 5-Year Contribution Margin ($mm) | C25: =NPV(WACC,C23:G23) -> -10.803831
B27: SMALL BUSINESS BANKING
B28: Revenue ($mm) | C28: ='Product Mix'!E$8*(1+'Product Mix'!E$19) -> 210 | D28: =C28*(1+'Product Mix'!E$19) -> 210 | E28: =D28*(1+'Product Mix'!E$19) -> 210 | F28: =E28*(1+'Product Mix'!E$19) -> 210 | G28: =F28*(1+'Product Mix'!E$19) -> 210
B29: Expense-to-Revenue Ratio (%) | C29: ='Product Mix'!E$32*(1-Sel_OpexEfficiency) -> 0.27332486 | D29: =C29*(1-Sel_OpexEfficiency) -> 0.27059161 | E29: =D29*(1-Sel_OpexEfficiency) -> 0.26788569 | F29: =E29*(1-Sel_OpexEfficiency) -> 0.26520684 | G29: =F29*(1-Sel_OpexEfficiency) -> 0.26255477
B30: Total Operating Expense ($mm) | C30: =C28*C29 -> 57.39822 | D30: =D28*D29 -> 56.824238 | E30: =E28*E29 -> 56.255995 | F30: =F28*F29 -> 55.693435 | G30: =G28*G29 -> 55.136501
B31: Gross Profit ($mm) | C31: =C28*'Product Mix'!E$15 -> 96.6 | D31: =D28*'Product Mix'!E$15 -> 96.6 | E31: =E28*'Product Mix'!E$15 -> 96.6 | F31: =F28*'Product Mix'!E$15 -> 96.6 | G31: =G28*'Product Mix'!E$15 -> 96.6
B32: Contribution Margin ($mm) | C32: =C31-C30 -> 39.20178 | D32: =D31-D30 -> 39.775762 | E32: =E31-E30 -> 40.344005 | F32: =F31-F30 -> 40.906565 | G32: =G31-G30 -> 41.463499
B33: Contribution Margin (% of Revenue) | C33: =C32/C28 -> 0.18667514 | D33: =D32/D28 -> 0.18940839 | E33: =E32/E28 -> 0.19211431 | F33: =F32/F28 -> 0.19479316 | G33: =G32/G28 -> 0.19744523
B34: NPV of 5-Year Contribution Margin ($mm) | C34: =NPV(WACC,C32:G32) -> 152.50686
B36: WEALTH & AFFLUENT BANKING
B37: Revenue ($mm) | C37: ='Product Mix'!F$8*(1+'Product Mix'!F$19) -> 165 | D37: =C37*(1+'Product Mix'!F$19) -> 165 | E37: =D37*(1+'Product Mix'!F$19) -> 165 | F37: =E37*(1+'Product Mix'!F$19) -> 165 | G37: =F37*(1+'Product Mix'!F$19) -> 165
B38: Expense-to-Revenue Ratio (%) | C38: ='Product Mix'!F$32*(1-Sel_OpexEfficiency) -> 0.26622 | D38: =C38*(1-Sel_OpexEfficiency) -> 0.2635578 | E38: =D38*(1-Sel_OpexEfficiency) -> 0.26092222 | F38: =E38*(1-Sel_OpexEfficiency) -> 0.258313 | G38: =F38*(1-Sel_OpexEfficiency) -> 0.25572987
B39: Total Operating Expense ($mm) | C39: =C37*C38 -> 43.9263 | D39: =D37*D38 -> 43.487037 | E39: =E37*E38 -> 43.052167 | F39: =F37*F38 -> 42.621645 | G39: =G37*G38 -> 42.195429
B40: Gross Profit ($mm) | C40: =C37*'Product Mix'!F$15 -> 66 | D40: =D37*'Product Mix'!F$15 -> 66 | E40: =E37*'Product Mix'!F$15 -> 66 | F40: =F37*'Product Mix'!F$15 -> 66 | G40: =G37*'Product Mix'!F$15 -> 66
B41: Contribution Margin ($mm) | C41: =C40-C39 -> 22.0737 | D41: =D40-D39 -> 22.512963 | E41: =E40-E39 -> 22.947833 | F41: =F40-F39 -> 23.378355 | G41: =G40-G39 -> 23.804571
B42: Contribution Margin (% of Revenue) | C42: =C41/C37 -> 0.13378 | D42: =D41/D37 -> 0.1364422 | E42: =E41/E37 -> 0.13907778 | F42: =F41/F37 -> 0.141687 | G42: =G41/G37 -> 0.14427013
B43: NPV of 5-Year Contribution Margin ($mm) | C43: =NPV(WACC,C41:G41) -> 86.662298
B45: TOTAL COMPANY (ALL PRODUCTS)
B46: Total Revenue ($mm) | C46: =C10+C19+C28+C37 -> 1195 | D46: =D10+D19+D28+D37 -> 1195 | E46: =E10+E19+E28+E37 -> 1195 | F46: =F10+F19+F28+F37 -> 1195 | G46: =G10+G19+G28+G37 -> 1195
B47: Total Operating Expense ($mm) | C47: =C12+C21+C30+C39 -> 389.98377 | D47: =D12+D21+D30+D39 -> 386.08393 | E47: =E12+E21+E30+E39 -> 382.22309 | F47: =F12+F21+F30+F39 -> 378.40086 | G47: =G12+G21+G30+G39 -> 374.61685
B48: Total Contribution Margin ($mm) | C48: =C14+C23+C32+C41 -> 159.01623 | D48: =D14+D23+D32+D41 -> 162.91607 | E48: =E14+E23+E32+E41 -> 166.77691 | F48: =F14+F23+F32+F41 -> 170.59914 | G48: =G14+G23+G32+G41 -> 174.38315
...

Sheet Sensitivity & Scenarios
A1: SENSITIVITY & SCENARIO COMPARISON
B3: Part A recomputes Year-5 outcomes independently for all three scenarios. Part B tests one variable at a time, holding others at Product Mix current-state values.
B6: PART A — SCENARIO COMPARISON: YEAR 5 OUTCOMES (COMPANY TOTAL)
B7: Metric | C7: Base Case | D7: Upside | E7: Downside
B8: Year 5 Total Revenue ($mm) | C8: ='Product Mix'!$G$8*(1+Assumptions!$C$9)^5 -> 1676.0493 | D8: ='Product Mix'!$G$8*(1+Assumptions!$D$9)^5 -> 2013.6445 | E8: ='Product Mix'!$G$8*(1+Assumptions!$E$9)^5 -> 1319.3766
B9: Year 5 Expense-to-Revenue Ratio (%) | C9: ='Product Mix'!$G$32*(1-Assumptions!$C$15)^5 -> 0.31348691 | D9: ='Product Mix'!$G$32*(1-Assumptions!$D$15)^5 -> 0.29797087 | E9: ='Product Mix'!$G$32*(1-Assumptions!$E$15)^5 -> 0.34645777
B10: Year 5 Total Operating Expense ($mm) | C10: =C8*C9 -> 525.41952 | D10: =D8*D9 -> 600.00741 | E10: =E8*E9 -> 457.10826
B11: Year 5 Gross Profit ($mm) | C11: =C8*('Product Mix'!G29/'Product Mix'!G8) -> 770.0009 | D11: =D8*('Product Mix'!G29/'Product Mix'!G8) -> 925.09693 | E11: =E8*('Product Mix'!G29/'Product Mix'!G8) -> 606.14036
B12: Year 5 Contribution Margin ($mm) | C12: =C11-C10 -> 244.58138 | D12: =D11-D10 -> 325.08952 | E12: =E11-E10 -> 149.0321
B13: Year 5 Contribution Margin (% of Revenue) | C13: =C12/C8 -> 0.14592732 | D13: =D12/D8 -> 0.16144335 | E13: =E12/E8 -> 0.11295646
B15: PART B — SINGLE-VARIABLE SENSITIVITY: IMPACT ON CURRENT-YEAR BLENDED CONTRIBUTION MARGIN
B16: Tests one driver at a time, holding all others at Product Mix current-state values.
B17: Marketing Spend Delta | C17: -2.0 pp | D17: -1.0 pp | E17: Base | F17: +1.0 pp | G17: +2.0 pp
B18: Blended Contribution Margin ($mm) | C18: ='Product Mix'!$G$29-('Product Mix'!$G$28+('Product Mix'!$G$8*-0.02)) -> 178.977 | D18: ='Product Mix'!$G$29-('Product Mix'!$G$28+('Product Mix'!$G$8*-0.01)) -> 167.027 | E18: ='Product Mix'!$G$29-('Product Mix'!$G$28+('Product Mix'!$G$8*0)) -> 155.077 | F18: ='Product Mix'!$G$29-('Product Mix'!$G$28+('Product Mix'!$G$8*0.01)) -> 143.127 | G18: ='Product Mix'!$G$29-('Product Mix'!$G$28+('Product Mix'!$G$8*0.02)) -> 131.177
B20: Customer Acquisition Cost (CAC) Delta | C20: -20% | D20: -10% | E20: Base | F20: +10% | G20: +20%
B21: Blended LTV : CAC Ratio (x) | C21: ='Product Mix'!$G$35/((SUM('Product Mix'!C21:F21)*1000000/SUM('Product Mix'!C11:F11)/1000)*(1+-0.2)) -> 3.6498407 | D21: ='Product Mix'!$G$35/((SUM('Product Mix'!C21:F21)*1000000/SUM('Product Mix'!C11:F11)/1000)*(1+-0.1)) -> 3.2443028 | E21: ='Product Mix'!$G$35/((SUM('Product Mix'!C21:F21)*1000000/SUM('Product Mix'!C11:F11)/1000)*(1+0)) -> 2.9198725 | F21: ='Product Mix'!$G$35/((SUM('Product Mix'!C21:F21)*1000000/SUM('Product Mix'!C11:F11)/1000)*(1+0.1)) -> 2.6544296 | G21: ='Product Mix'!$G$35/((SUM('Product Mix'!C21:F21)*1000000/SUM('Product Mix'!C11:F11)/1000)*(1+0.2)) -> 2.4332271
B22: Blended CAC Payback Period (months) | C22: =((SUM('Product Mix'!C21:F21)*1000000/SUM('Product Mix'!C11:F11)/1000)*(1+-0.2))/(('Product Mix'!$G$34*('Product Mix'!$G$29/'Product Mix'!$G$8))/12) -> 19.216648 | D22: =((SUM('Product Mix'!C21:F21)*1000000/SUM('Product Mix'!C11:F11)/1000)*(1+-0.1))/(('Product Mix'!$G$34*('Product Mix'!$G$29/'Product Mix'!$G$8))/12) -> 21.61873 | E22: =((SUM('Product Mix'!C21:F21)*1000000/SUM('Product Mix'!C11:F11)/1000)*(1+0))/(('Product Mix'!$G$34*('Product Mix'!$G$29/'Product Mix'!$G$8))/12) -> 24.020811 | F22: =((SUM('Product Mix'!C21:F21)*1000000/SUM('Product Mix'!C11:F11)/1000)*(1+0.1))/(('Product Mix'!$G$34*('Product Mix'!$G$29/'Product Mix'!$G$8))/12) -> 26.422892 | G22: =((SUM('Product Mix'!C21:F21)*1000000/SUM('Product Mix'!C11:F11)/1000)*(1+0.2))/(('Product Mix'!$G$34*('Product Mix'!$G$29/'Product Mix'!$G$8))/12) -> 28.824973
B24: Revenue Growth Rate Delta | C24: -3.0 pp | D24: Base | E24: +3.0 pp
B25: Year 5 Total Revenue ($mm) | C25: ='Product Mix'!$G$8*(1+Sel_GrowthRate+-0.03)^5 -> 1453.9002 | D25: ='Product Mix'!$G$8*(1+Sel_GrowthRate+0)^5 -> 1676.0493 | E25: ='Product Mix'!$G$8*(1+Sel_GrowthRate+0.03)^5 -> 1924.5594

Sheet Dashboard
A1: PRODUCT MANAGEMENT EXPENSE & PRODUCT-MIX DASHBOARD
K2: ="Scenario: "&Assumptions!$C$5 -> Scenario: Base Case
B3: Total Current Revenue | D3: Blended Contribution Margin | F3: Blended Contribution Margin % | H3: Blended LTV : CAC Ratio | J3: Year 5 Projected Revenue | L3: 5-Yr NPV of Contribution Margin
B4: ='Product Mix'!$G$8 -> 1195 | D4: ='Product Mix'!$G$30 -> 155.077 | F4: ='Product Mix'!$G$31 -> 0.12977155 | H4: ='Product Mix'!$G$36 -> 2.9198725 | J4: ='5-Yr Projection'!$G$46 -> 1195 | L4: ='5-Yr Projection'!$C$52 -> 629.30327
B6: All figures reference Product Mix (current-state) and 5-Yr Projection (Active Scenario). Change the scenario or any blue input to update this view.
B8: CHART DATA (LINKED — DO NOT EDIT)
B9: Product | C9: Credit Cards | D9: Retail Banking (Deposits & Digital) | E9: Small Business Banking | F9: Wealth & Affluent Banking
B10: Contribution Margin % | C10: ='Product Mix'!C$31 -> 0.2109375 | D10: ='Product Mix'!D$31 -> -0.018897059 | E10: ='Product Mix'!E$31 -> 0.18391429 | F10: ='Product Mix'!F$31 -> 0.13109091
B11: LTV:CAC Ratio | C11: ='Product Mix'!C$36 -> 5.4985681 | D11: ='Product Mix'!D$36 -> 0.67132867 | E11: ='Product Mix'!E$36 -> 12.241794 | F11: ='Product Mix'!F$36 -> 15.438596
B13: Expense Category | C13: Amount ($mm)
B14: Marketing | C14: ='Product Mix'!$G$23 -> 112.478
B15: Technology | C15: ='Product Mix'!$G$24 -> 116.04
B16: Compliance & Risk | C16: ='Product Mix'!$G$25 -> 68.625
B17: Headcount | C17: ='Product Mix'!$G$26 -> 25.08
B18: Corporate Overhead | C18: ='Product Mix'!$G$27 -> 71.7
B20: Year | C20: ='5-Yr Projection'!C6 -> FY2027 | D20: ='5-Yr Projection'!D6 -> FY2028 | E20: ='5-Yr Projection'!E6 -> FY2029 | F20: ='5-Yr Projection'!F6 -> FY2030 | G20: ='5-Yr Projection'!G6 -> FY2031
B21: Total Revenue ($mm) | C21: ='5-Yr Projection'!C46 -> 1195 | D21: ='5-Yr Projection'!D46 -> 1195 | E21: ='5-Yr Projection'!E46 -> 1195 | F21: ='5-Yr Projection'!F46 -> 1195 | G21: ='5-Yr Projection'!G46 -> 1195
B22: Total Opex ($mm) | C22: ='5-Yr Projection'!C47 -> 389.98377 | D22: ='5-Yr Projection'!D47 -> 386.08393 | E22: ='5-Yr Projection'!E47 -> 382.22309 | F22: ='5-Yr Projection'!F47 -> 378.40086 | G22: ='5-Yr Projection'!G47 -> 374.61685
B23: Contribution Margin ($mm) | C23: ='5-Yr Projection'!C48 -> 159.01623 | D23: ='5-Yr Projection'!D48 -> 162.91607 | E23: ='5-Yr Projection'!E48 -> 166.77691 | F23: ='5-Yr Projection'!F48 -> 170.59914 | G23: ='5-Yr Projection'!G48 -> 174.38315
